<?xml version="1.0" ?>
<sdf version='1.7'>
  <world name='default'>
    <light name='sun' type='directional'>
      <cast_shadows>1</cast_shadows>
      <pose>0 0 10 0 -0 0</pose>
      <diffuse>0.8 0.8 0.8 1</diffuse>
      <specular>0.2 0.2 0.2 1</specular>
      <attenuation>
        <range>1000</range>
        <constant>0.9</constant>
        <linear>0.01</linear>
        <quadratic>0.001</quadratic>
      </attenuation>
      <direction>-0.5 0.1 -0.9</direction>
      <spot>
        <inner_angle>0</inner_angle>
        <outer_angle>0</outer_angle>
        <falloff>0</falloff>
      </spot>
    </light>
    <model name='ground_plane'>
      <static>1</static>
      <link name='link'>
        <collision name='collision'>
          <geometry>
            <plane>
              <normal>0 0 1</normal>
              <size>100 100</size>
            </plane>
          </geometry>
          <surface>
            <contact>
              <collide_bitmask>65535</collide_bitmask>
              <ode/>
            </contact>
            <friction>
              <ode>
                <mu>100</mu>
                <mu2>50</mu2>
              </ode>
              <torsional>
                <ode/>
              </torsional>
            </friction>
            <bounce/>
          </surface>
          <max_contacts>10</max_contacts>
        </collision>
        <visual name='visual'>
          <cast_shadows>0</cast_shadows>
          <geometry>
            <plane>
              <normal>0 0 1</normal>
              <size>100 100</size>
            </plane>
          </geometry>
          <material>
            <script>
              <uri>file://media/materials/scripts/gazebo.material</uri>
              <name>Gazebo/White</name>
            </script>
          </material>
        </visual>
        <self_collide>0</self_collide>
        <enable_wind>0</enable_wind>
        <kinematic>0</kinematic>
      </link>
    </model>
    <model name='mbot'>
      <pose>-20 0 0 0 -0 0</pose>
      <frame name='tankbot::__model__' attached_to='tankbot::chassis'>
        <pose relative_to='__model__'>0 0 0 0 -0 0</pose>
      </frame>
      <link name='tankbot::chassis'>
        <pose relative_to='tankbot::__model__'>0 0 0.135 0 -0 0</pose>
        <inertial>
          <pose>0.0465 0 0 0 -0 0</pose>
          <mass>2</mass>
          <inertia>
            <ixx>0.0125927</ixx>
            <iyy>0.0408542</iyy>
            <izz>0.0438135</izz>
            <ixy>0</ixy>
            <ixz>0</ixz>
            <iyz>0</iyz>
          </inertia>
        </inertial>
        <collision name='collision'>
          <geometry>
            <box>
              <size>0.465 0.216 0.17</size>
            </box>
          </geometry>
          <max_contacts>10</max_contacts>
          <surface>
            <contact>
              <ode/>
            </contact>
            <bounce/>
            <friction>
              <torsional>
                <ode/>
              </torsional>
              <ode/>
            </friction>
          </surface>
        </collision>
        <visual name='visual'>
          <geometry>
            <box>
              <size>0.465 0.216 0.17</size>
            </box>
          </geometry>
          <material>
            <script>
              <uri>file://media/materials/scripts/gazebo.material</uri>
              <name>Gazebo/Grey</name>
            </script>
          </material>
        </visual>
        <self_collide>0</self_collide>
        <enable_wind>0</enable_wind>
        <kinematic>0</kinematic>
      </link>
      <link name='tankbot::wheel_fl'>
        <pose relative_to='tankbot::__model__'>0.1395 0.142 0.05 -1.5708 -0.087266 0</pose>
        <inertial>
          <mass>0.25</mass>
          <inertia>
            <ixx>0.000189583</ixx>
            <iyy>0.000189583</iyy>
            <izz>0.0003125</izz>
            <ixy>0</ixy>
            <ixz>0</ixz>
            <iyz>0</iyz>
          </inertia>
          <pose>0 0 0 0 -0 0</pose>
        </inertial>
        <collision name='collision'>
          <geometry>
            <cylinder>
              <radius>0.05</radius>
              <length>0.04</length>
            </cylinder>
          </geometry>
          <max_contacts>10</max_contacts>
          <surface>
            <contact>
              <ode/>
            </contact>
            <bounce/>
            <friction>
              <torsional>
                <ode/>
              </torsional>
              <ode/>
            </friction>
          </surface>
        </collision>
        <visual name='tankbot::wheel_fl'>
          <geometry>
            <cylinder>
              <radius>0.05</radius>
              <length>0.04</length>
            </cylinder>
          </geometry>
          <material>
            <script>
              <uri>file://media/materials/scripts/gazebo.material</uri>
              <name>Gazebo/Black</name>
            </script>
          </material>
        </visual>
        <self_collide>0</self_collide>
        <enable_wind>0</enable_wind>
        <kinematic>0</kinematic>
      </link>
      <joint name='tankbot::wheel_fl_drive' type='revolute'>
        <parent>tankbot::chassis</parent>
        <child>tankbot::wheel_fl</child>
        <axis>
          <xyz>0 0 1</xyz>
          <limit>
            <lower>-1e+16</lower>
            <upper>1e+16</upper>
          </limit>
          <dynamics>
            <spring_reference>0</spring_reference>
            <spring_stiffness>0</spring_stiffness>
          </dynamics>
        </axis>
      </joint>
      <link name='tankbot::chain_l_up'>
        <pose relative_to='tankbot::__model__'>0.0098 0.14 0.1 0 -0 0</pose>
        <gravity>0</gravity>
        <collision name='collision'>
          <geometry>
            <box>
              <size>0.28 0.04 0.01</size>
            </box>
          </geometry>
          <max_contacts>10</max_contacts>
          <surface>
            <contact>
              <ode/>
            </contact>
            <bounce/>
            <friction>
              <torsional>
                <ode/>
              </torsional>
              <ode/>
            </friction>
          </surface>
        </collision>
        <visual name='visual'>
          <geometry>
            <box>
              <size>0.28 0.04 0.01</size>
            </box>
          </geometry>
          <material>
            <script>
              <uri>file://media/materials/scripts/gazebo.material</uri>
              <name>Gazebo/Black</name>
            </script>
          </material>
        </visual>
        <self_collide>0</self_collide>
        <inertial>
          <pose>0 0 0 0 -0 0</pose>
          <inertia>
            <ixx>1</ixx>
            <ixy>0</ixy>
            <ixz>0</ixz>
            <iyy>1</iyy>
            <iyz>0</iyz>
            <izz>1</izz>
          </inertia>
          <mass>1</mass>
        </inertial>
        <enable_wind>0</enable_wind>
        <kinematic>0</kinematic>
      </link>
      <link name='tankbot::chain_r_up'>
        <pose relative_to='tankbot::__model__'>0.0098 -0.14 0.1 0 -0 0</pose>
        <gravity>0</gravity>
        <collision name='collision'>
          <geometry>
            <box>
              <size>0.28 0.04 0.01</size>
            </box>
          </geometry>
          <max_contacts>10</max_contacts>
          <surface>
            <contact>
              <ode/>
            </contact>
            <bounce/>
            <friction>
              <torsional>
                <ode/>
              </torsional>
              <ode/>
            </friction>
          </surface>
        </collision>
        <visual name='visual'>
          <geometry>
            <box>
              <size>0.28 0.04 0.01</size>
            </box>
          </geometry>
          <material>
            <script>
              <uri>file://media/materials/scripts/gazebo.material</uri>
              <name>Gazebo/Black</name>
            </script>
          </material>
        </visual>
        <self_collide>0</self_collide>
        <inertial>
          <pose>0 0 0 0 -0 0</pose>
          <inertia>
            <ixx>1</ixx>
            <ixy>0</ixy>
            <ixz>0</ixz>
            <iyy>1</iyy>
            <iyz>0</iyz>
            <izz>1</izz>
          </inertia>
          <mass>1</mass>
        </inertial>
        <enable_wind>0</enable_wind>
        <kinematic>0</kinematic>
      </link>
      <joint name='tankbot::chain_up_joint' type='revolute'>
        <parent>tankbot::chassis</parent>
        <child>tankbot::chain_r_up</child>
      </joint>
      <joint name='tankbot::chain_up_2_joint' type='revolute'>
        <parent>tankbot::chassis</parent>
        <child>tankbot::chain_l_up</child>
      </joint>
      <link name='tankbot::wheel_fr'>
        <pose relative_to='tankbot::__model__'>0.1395 -0.142 0.05 -1.5708 -0.087266 0</pose>
        <inertial>
          <mass>0.25</mass>
          <inertia>
            <ixx>0.000189583</ixx>
            <iyy>0.000189583</iyy>
            <izz>0.0003125</izz>
            <ixy>0</ixy>
            <ixz>0</ixz>
            <iyz>0</iyz>
          </inertia>
          <pose>0 0 0 0 -0 0</pose>
        </inertial>
        <collision name='collision'>
          <geometry>
            <cylinder>
              <radius>0.05</radius>
              <length>0.04</length>
            </cylinder>
          </geometry>
          <max_contacts>10</max_contacts>
          <surface>
            <contact>
              <ode/>
            </contact>
            <bounce/>
            <friction>
              <torsional>
                <ode/>
              </torsional>
              <ode/>
            </friction>
          </surface>
        </collision>
        <visual name='visual'>
          <geometry>
            <cylinder>
              <radius>0.05</radius>
              <length>0.04</length>
            </cylinder>
          </geometry>
          <material>
            <script>
              <uri>file://media/materials/scripts/gazebo.material</uri>
              <name>Gazebo/Black</name>
            </script>
          </material>
        </visual>
        <self_collide>0</self_collide>
        <enable_wind>0</enable_wind>
        <kinematic>0</kinematic>
      </link>
      <joint name='tankbot::wheel_fr_drive' type='revolute'>
        <parent>tankbot::chassis</parent>
        <child>tankbot::wheel_fr</child>
        <axis>
          <xyz>0 0 1</xyz>
          <limit>
            <lower>-1e+16</lower>
            <upper>1e+16</upper>
          </limit>
          <dynamics>
            <spring_reference>0</spring_reference>
            <spring_stiffness>0</spring_stiffness>
          </dynamics>
        </axis>
      </joint>
      <link name='tankbot::wheel_rl'>
        <pose relative_to='tankbot::__model__'>-0.1395 0.142 0.05 -1.5708 0 0</pose>
        <inertial>
          <mass>0.25</mass>
          <inertia>
            <ixx>0.000189583</ixx>
            <iyy>0.000189583</iyy>
            <izz>0.0003125</izz>
            <ixy>0</ixy>
            <ixz>0</ixz>
            <iyz>0</iyz>
          </inertia>
          <pose>0 0 0 0 -0 0</pose>
        </inertial>
        <collision name='collision'>
          <geometry>
            <cylinder>
              <radius>0.05</radius>
              <length>0.04</length>
            </cylinder>
          </geometry>
          <max_contacts>10</max_contacts>
          <surface>
            <contact>
              <ode/>
            </contact>
            <bounce/>
            <friction>
              <torsional>
                <ode/>
              </torsional>
              <ode/>
            </friction>
          </surface>
        </collision>
        <visual name='visual'>
          <geometry>
            <cylinder>
              <radius>0.05</radius>
              <length>0.04</length>
            </cylinder>
          </geometry>
          <material>
            <script>
              <uri>file://media/materials/scripts/gazebo.material</uri>
              <name>Gazebo/Black</name>
            </script>
          </material>
        </visual>
        <self_collide>0</self_collide>
        <enable_wind>0</enable_wind>
        <kinematic>0</kinematic>
      </link>
      <joint name='tankbot::wheel_rl_drive' type='revolute'>
        <parent>tankbot::chassis</parent>
        <child>tankbot::wheel_rl</child>
        <axis>
          <xyz>0 0 1</xyz>
          <limit>
            <lower>-1e+16</lower>
            <upper>1e+16</upper>
          </limit>
          <dynamics>
            <spring_reference>0</spring_reference>
            <spring_stiffness>0</spring_stiffness>
          </dynamics>
        </axis>
      </joint>
      <link name='tankbot::wheel_rr'>
        <pose relative_to='tankbot::__model__'>-0.1395 -0.142 0.05 -1.5708 0 0</pose>
        <inertial>
          <mass>0.25</mass>
          <inertia>
            <ixx>0.000189583</ixx>
            <iyy>0.000189583</iyy>
            <izz>0.0003125</izz>
            <ixy>0</ixy>
            <ixz>0</ixz>
            <iyz>0</iyz>
          </inertia>
          <pose>0 0 0 0 -0 0</pose>
        </inertial>
        <collision name='collision'>
          <geometry>
            <cylinder>
              <radius>0.05</radius>
              <length>0.04</length>
            </cylinder>
          </geometry>
          <max_contacts>10</max_contacts>
          <surface>
            <contact>
              <ode/>
            </contact>
            <bounce/>
            <friction>
              <torsional>
                <ode/>
              </torsional>
              <ode/>
            </friction>
          </surface>
        </collision>
        <visual name='visual'>
          <geometry>
            <cylinder>
              <radius>0.05</radius>
              <length>0.04</length>
            </cylinder>
          </geometry>
          <material>
            <script>
              <uri>file://media/materials/scripts/gazebo.material</uri>
              <name>Gazebo/Black</name>
            </script>
          </material>
        </visual>
        <self_collide>0</self_collide>
        <enable_wind>0</enable_wind>
        <kinematic>0</kinematic>
      </link>
      <joint name='tankbot::wheel_rr_drive' type='revolute'>
        <parent>tankbot::chassis</parent>
        <child>tankbot::wheel_rr</child>
        <axis>
          <xyz>0 0 1</xyz>
          <limit>
            <lower>-1e+16</lower>
            <upper>1e+16</upper>
          </limit>
          <dynamics>
            <spring_reference>0</spring_reference>
            <spring_stiffness>0</spring_stiffness>
          </dynamics>
        </axis>
      </joint>
      <frame name='tankbot::ultrasonic_sensor::__model__' attached_to='tankbot::ultrasonic_sensor::link'>
        <pose relative_to='tankbot::__model__'>0.18 0 0.24 0 -0 0</pose>
      </frame>
      <link name='tankbot::ultrasonic_sensor::link'>
        <inertial>
          <mass>0.1</mass>
          <pose>0 0 0 0 -0 0</pose>
          <inertia>
            <ixx>1</ixx>
            <ixy>0</ixy>
            <ixz>0</ixz>
            <iyy>1</iyy>
            <iyz>0</iyz>
            <izz>1</izz>
          </inertia>
        </inertial>
        <visual name='visual'>
          <geometry>
            <cylinder>
              <radius>0.04</radius>
              <length>0.04</length>
            </cylinder>
          </geometry>
        </visual>
        <collision name='collision-base'>
          <pose>0 0 -0.0145 0 -0 0</pose>
          <geometry>
            <box>
              <size>0.05 0.05 0.041</size>
            </box>
          </geometry>
          <max_contacts>10</max_contacts>
          <surface>
            <contact>
              <ode/>
            </contact>
            <bounce/>
            <friction>
              <torsional>
                <ode/>
              </torsional>
              <ode/>
            </friction>
          </surface>
        </collision>
        <collision name='collision-top'>
          <pose>0 0 0.0205 0 -0 0</pose>
          <geometry>
            <cylinder>
              <radius>0.021</radius>
              <length>0.029</length>
            </cylinder>
          </geometry>
          <max_contacts>10</max_contacts>
          <surface>
            <contact>
              <ode/>
            </contact>
            <bounce/>
            <friction>
              <torsional>
                <ode/>
              </torsional>
              <ode/>
            </friction>
          </surface>
        </collision>
        <sensor name='sonar' type='sonar'>
          <pose>0.04 0 0 0 1.5 3.14</pose>
          <sonar>
            <min>0</min>
            <max>3</max>
            <radius>0.3</radius>
          </sonar>
          <plugin name='sonar' filename='libSonarPlugin.so'/>
          <always_on>1</always_on>
          <update_rate>30</update_rate>
          <visualize>1</visualize>
        </sensor>
        <pose relative_to='tankbot::ultrasonic_sensor::__model__'>0 0 0 0 -0 0</pose>
        <self_collide>0</self_collide>
        <enable_wind>0</enable_wind>
        <kinematic>0</kinematic>
      </link>
      <joint name='tankbot::sonar_joint' type='fixed'>
        <child>tankbot::ultrasonic_sensor::link</child>
        <parent>tankbot::chassis</parent>
      </joint>
      <frame name='tankbot::camera_sensor::__model__' attached_to='tankbot::camera_sensor::link'>
        <pose relative_to='tankbot::__model__'>0.2 0 0.04 0 1.57 0</pose>
      </frame>
      <frame name='tankbot::camera_sensor_2::__model__' attached_to='tankbot::camera_sensor::link_2'>
        <pose relative_to='tankbot::__model__'>0.15 -0.07 0.04 0 1.57 0</pose>
      </frame>
      <link name='tankbot::camera_sensor::link'>
        <inertial>
          <mass>0.1</mass>
          <pose>0 0 0 0 -0 0</pose>
          <inertia>
            <ixx>1</ixx>
            <ixy>0</ixy>
            <ixz>0</ixz>
            <iyy>1</iyy>
            <iyz>0</iyz>
            <izz>1</izz>
          </inertia>
        </inertial>
        <visual name='visual'>
          <geometry>
            <box>
              <size>0.01 0.07 0.04</size>
            </box>
          </geometry>
          <material>
            <script>
              <uri>file://media/materials/scripts/gazebo.material</uri>
              <name>Gazebo/Red</name>
            </script>
          </material>
        </visual>
        <collision name='collision'>
          <pose>0 0 -0.0145 0 -0 0</pose>
          <geometry>
            <box>
              <size>0.01 0.07 0.04</size>
            </box>
          </geometry>
          <max_contacts>10</max_contacts>
          <surface>
            <contact>
              <ode/>
            </contact>
            <bounce/>
            <friction>
              <torsional>
                <ode/>
              </torsional>
              <ode/>
            </friction>
          </surface>
        </collision>
        <sensor name='camera' type='camera'>
          <camera>
            <horizontal_fov>1.39626</horizontal_fov>
            <image>
              <width>2</width>
              <height>2</height>
            </image>
            <clip>
              <near>0.02</near>
              <far>300</far>
            </clip>
          </camera>
          <always_on>1</always_on>
          <update_rate>10</update_rate>
          <visualize>1</visualize>
          <plugin name='camera_controller' filename='libCameraPlugin.so'/>
        </sensor>
        <pose relative_to='tankbot::camera_sensor::__model__'>0 0 0 0 -0 0</pose>
        <self_collide>0</self_collide>
        <enable_wind>0</enable_wind>
        <kinematic>0</kinematic>
      </link>
      <link name='tankbot::camera_sensor::link_2'>
        <inertial>
          <mass>0.1</mass>
          <pose>0 0 0 0 -0 0</pose>
          <inertia>
            <ixx>1</ixx>
            <ixy>0</ixy>
            <ixz>0</ixz>
            <iyy>1</iyy>
            <iyz>0</iyz>
            <izz>1</izz>
          </inertia>
        </inertial>
        <visual name='visual'>
          <geometry>
            <box>
              <size>0.01 0.07 0.04</size>
            </box>
          </geometry>
          <material>
            <script>
              <uri>file://media/materials/scripts/gazebo.material</uri>
              <name>Gazebo/Red</name>
            </script>
          </material>
        </visual>
        <collision name='collision'>
          <pose>0 0 -0.0145 0 -0 0</pose>
          <geometry>
            <box>
              <size>0.01 0.07 0.04</size>
            </box>
          </geometry>
          <max_contacts>10</max_contacts>
          <surface>
            <contact>
              <ode/>
            </contact>
            <bounce/>
            <friction>
              <torsional>
                <ode/>
              </torsional>
              <ode/>
            </friction>
          </surface>
        </collision>
        <sensor name='camera' type='camera'>
          <camera>
            <horizontal_fov>1.39626</horizontal_fov>
            <image>
              <width>2</width>
              <height>2</height>
            </image>
            <clip>
              <near>0.02</near>
              <far>300</far>
            </clip>
          </camera>
          <always_on>1</always_on>
          <update_rate>10</update_rate>
          <visualize>1</visualize>
          <plugin name='camera_controller' filename='libCameraPlugin.so'/>
        </sensor>
        <pose relative_to='tankbot::camera_sensor_2::__model__'>0 0 0 0 -0 0</pose>
        <self_collide>0</self_collide>
        <enable_wind>0</enable_wind>
        <kinematic>0</kinematic>
      </link>
      <frame name='tankbot::microphone_sensor::__model__' attached_to='tankbot::microphone_sensor::link'>
        <pose relative_to='tankbot::__model__'>0 0 0.23 0 -0 0</pose>
      </frame>
      <link name='tankbot::microphone_sensor::link'>
        <inertial>
          <mass>0.1</mass>
          <pose>0 0 0 0 -0 0</pose>
          <inertia>
            <ixx>1</ixx>
            <ixy>0</ixy>
            <ixz>0</ixz>
            <iyy>1</iyy>
            <iyz>0</iyz>
            <izz>1</izz>
          </inertia>
        </inertial>
        <visual name='visual'>
          <geometry>
            <box>
              <size>0.01 0.01 0.01</size>
            </box>
          </geometry>
          <material>
            <script>
              <uri>file://media/materials/scripts/gazebo.material</uri>
              <name>Gazebo/Grey</name>
            </script>
          </material>
        </visual>
        <collision name='collision'>
          <pose>0 0 0 0 -0 0</pose>
          <geometry>
            <box>
              <size>0.01 0.01 0.01</size>
            </box>
          </geometry>
          <max_contacts>10</max_contacts>
          <surface>
            <contact>
              <ode/>
            </contact>
            <bounce/>
            <friction>
              <torsional>
                <ode/>
              </torsional>
              <ode/>
            </friction>
          </surface>
        </collision>
        <pose relative_to='tankbot::microphone_sensor::__model__'>0 0 0 0 -0 0</pose>
        <self_collide>0</self_collide>
        <enable_wind>0</enable_wind>
        <kinematic>0</kinematic>
      </link>
      <plugin name='microphone_controller' filename='libmicrophone_control_plugin.so'/>
      <joint name='tankbot::camera_joint' type='fixed'>
        <child>tankbot::camera_sensor::link</child>
        <parent>tankbot::chassis</parent>
      </joint>
      <joint name='tankbot::camera_joint_2' type='fixed'>
        <child>tankbot::camera_sensor::link_2</child>
        <parent>tankbot::chassis</parent>
      </joint>
      <plugin name='tankbot_control' filename='libtank_control_plugin.so'/>
    </model>
    <gravity>0 0 -9.8</gravity>
    <magnetic_field>6e-06 2.3e-05 -4.2e-05</magnetic_field>
    <atmosphere type='adiabatic'/>
    <physics type='ode'>
      <max_step_size>0.001</max_step_size>
      <real_time_factor>1</real_time_factor>
      <real_time_update_rate>1000</real_time_update_rate>
    </physics>
    <scene>
      <ambient>0.4 0.4 0.4 1</ambient>
      <background>0.7 0.7 0.7 1</background>
      <shadows>1</shadows>
    </scene>
    <wind/>
    <spherical_coordinates>
      <surface_model>EARTH_WGS84</surface_model>
      <latitude_deg>0</latitude_deg>
      <longitude_deg>0</longitude_deg>
      <elevation>0</elevation>
      <heading_deg>0</heading_deg>
    </spherical_coordinates>
    <state world_name='default'>
      <sim_time>526 462000000</sim_time>
      <real_time>55 808410865</real_time>
      <wall_time>1605561084 317289053</wall_time>
      <iterations>55527</iterations>
      <model name='ground_plane'>
        <pose>0 0 0 0 -0 0</pose>
        <scale>1 1 1</scale>
        <link name='link'>
          <pose>0 0 0 0 -0 0</pose>
          <velocity>0 0 0 0 -0 0</velocity>
          <acceleration>0 0 0 0 -0 0</acceleration>
          <wrench>0 0 0 0 -0 0</wrench>
        </link>
      </model>
      <model name='mbot'>
        <pose>-14.6653 0.056172 -6e-06 1e-06 5e-06 0.010965</pose>
        <scale>1 1 1</scale>
        <link name='tankbot::chain_l_up'>
          <pose>-14.657 0.196271 0.099994 -0.00032 4e-06 0.010965</pose>
          <velocity>-1.1e-05 -0.000291 -0.005871 3e-06 0.00021 -2.8e-05</velocity>
          <acceleration>-0.025946 0.005355 -6.07365 -0.006981 0.636674 0.006468</acceleration>
          <wrench>-0.025946 0.005355 -6.07365 0 -0 0</wrench>
        </link>
        <link name='tankbot::chain_r_up'>
          <pose>-14.654 -0.083712 0.099994 -2e-06 5e-06 0.010965</pose>
          <velocity>-5e-06 -0.00029 -0.005996 1.1e-05 -0.000456 -3.6e-05</velocity>
          <acceleration>-0.001022 0.008857 -5.99482 0.005276 -0.481163 -0.031634</acceleration>
          <wrench>-0.001022 0.008857 -5.99482 0 -0 0</wrench>
        </link>
        <link name='tankbot::chassis'>
          <pose>-14.6653 0.056172 0.134994 1e-06 5e-06 0.010965</pose>
          <velocity>4e-06 -0.000304 -0.005986 6.4e-05 -0.000572 -4.4e-05</velocity>
          <acceleration>0.018814 0.02012 -6.05736 -0.295204 -0.826098 -0.056638</acceleration>
          <wrench>0.037628 0.040239 -12.1147 0 -0 0</wrench>
        </link>
        <link name='tankbot::microphone_sensor::link'>
          <pose>-91.9632 -1.24893 0.005001 8.7e-05 0.000121 0.007382</pose>
          <velocity>-6e-06 -2e-06 -4e-06 0.00035 -0.001177 0</velocity>
          <acceleration>-2.5e-05 2.4e-05 -4.9e-05 -0.004863 -0.004935 0</acceleration>
          <wrench>-2e-06 2e-06 -5e-06 0 -0 0</wrench>
        </link>
        <link name='tankbot::ultrasonic_sensor::link'>
          <pose>-14.4853 0.058146 0.239993 0 5e-06 0.010965</pose>
          <velocity>1.4e-05 -0.000339 -0.00597 0.000298 7.6e-05 -5e-06</velocity>
          <acceleration>0.095752 0.040784 -6.15743 -0.113456 0.686609 0.034534</acceleration>
          <wrench>0.009575 0.004078 -0.615743 0 -0 0</wrench>
        </link>
        <link name='tankbot::wheel_fl'>
          <pose>-14.5274 0.199693 0.049994 -1.5708 1.30781 0.010964</pose>
          <velocity>6.5e-05 -0.000289 -0.005976 -0.000599 -0.000249 -7.7e-05</velocity>
          <acceleration>0.095858 -0.08325 -5.99341 1.64924 0.402143 -0.243362</acceleration>
          <wrench>0.023965 -0.020812 -1.49835 0 -0 0</wrench>
        </link>
        <link name='tankbot::wheel_fr'>
          <pose>-14.5243 -0.08429 0.049994 1.5708 0.717563 -3.13063</pose>
          <velocity>-3.6e-05 -0.000287 -0.006106 -0.000115 0.000386 -3.2e-05</velocity>
          <acceleration>-0.061231 -0.064217 -6.10858 1.76542 -0.178183 0.21575</acceleration>
          <wrench>-0.015308 -0.016054 -1.52714 0 -0 0</wrench>
        </link>
        <link name='tankbot::wheel_rl'>
          <pose>-14.8064 0.196634 0.049995 -1.5708 0.994746 0.010959</pose>
          <velocity>-2.5e-05 -0.000291 -0.005803 0.00039 0.000233 -1.8e-05</velocity>
          <acceleration>-0.077129 -0.020296 -5.92327 -0.367507 0.013886 0.107324</acceleration>
          <wrench>-0.019282 -0.005074 -1.48082 0 -0 0</wrench>
        </link>
        <link name='tankbot::wheel_rr'>
          <pose>-14.8032 -0.087349 0.049994 1.5708 -1.17934 -3.13063</pose>
          <velocity>-1.5e-05 -0.000266 -0.005794 -0.000226 0.00063 -2.4e-05</velocity>
          <acceleration>-0.062669 -0.080628 -5.82211 2.42126 -0.39764 0.267186</acceleration>
          <wrench>-0.015667 -0.020157 -1.45553 0 -0 0</wrench>
        </link>
      </model>
      <light name='sun'>
        <pose>0 0 10 0 -0 0</pose>
      </light>
    </state>
    <gui fullscreen='0'>
      <camera name='user_camera'>
        <pose>-5.89127 0.040482 2.31936 0 0.208418 -3.09008</pose>
        <view_controller>orbit</view_controller>
        <projection_type>perspective</projection_type>
      </camera>
    </gui>
  </world>
</sdf>
